<?xml version="1.0" ?>
<!-- =================================================================================== -->
<!-- |    This document was autogenerated by xacro from repair_full.urdf.xacro         | -->
<!-- |    EDITING THIS FILE BY HAND IS NOT RECOMMENDED                                 | -->
<!-- =================================================================================== -->
<!-- xacro for generating the full urdf of the RePair platform (cage + bimanual robot) -->
<!-- is_sliding_wrist: whether to add a sliding joint along the wrist second d.o.f.
    (true -> yes), everything else -> no. This is used to generate the URDF for the optimization.  -->
<!-- gen_coll: whether to add the approximate collision  model of the platform -->
<!-- load_sol: whether to generate the URDF without the additional d.o.f. used by the co-design optimization.
Setting it to "true", allow to fix the additional d.o.f. to desired values 
(specified in the repair_urdf/config/arm_opt_mount_vals.yaml file) -->
<!-- use_updated_wrist: visual parameter. if true, we load the latest meshes (which are adapted to the
results of the optimization), otherwise we go with the old ones (generated for a spherical wrist) -->
<!-- xbot: if true, we add the gazebo tags necessary to use the URDF with XBot2 framework -->
<robot name="repair_full">
  <!-- below this value, Gazebo parser ignores links
To give some  perspective, a grain of sand weights  0.0000045 grams. So this corresponds to less than 1/4 of a grain of sand of
fake inertia -> it is acceptable. -->
  <!-- color -->
  <material name="darkblue">
    <color rgba="0.0 0.3 0.9 1"/>
  </material>
  <material name="darkred">
    <color rgba="0.55 0.0 0.0 1"/>
  </material>
  <material name="dark">
    <color rgba="0.6 0.6 0.6 1"/>
  </material>
  <!-- Reading some parameters from a YAML config file for the approximate collision model for RePair.
Links are approximated as spheres with hand-tuned radii and positions -->
  <!-- only something to avoid collisions between leg and ground plane when using Gaz. -->
  <!-- <xacro:if value="$(arg shorten_table_legs_coll)">

    <xacro:property name="leg_z_offset_gz" value="0.05" /> 

  </xacro:if>

    <xacro:property name="leg_z_offset_gz" value="0.0" /> 

  </xacro:unless> -->
  <link name="world">
  </link>
  <joint name="world_joint" type="fixed">
    <parent link="world"/>
    <origin rpy="0 0 0" xyz="0 0 0.520599"/>
    <child link="base_link"/>
  </joint>
  <link name="base_link">
    <!-- torso inertias + stuff attached to the sliding guide -->
    <inertial>
      <mass value="5.0"/>
      <origin xyz="0 0 0"/>
      <inertia ixx="0" ixy="0" ixz="0" iyy="0" iyz="0" izz="0"/>
    </inertial>
  </link>
  <joint name="r_arm_mount_joint" type="fixed">
    <origin rpy="0 0 0" xyz="0.0 -0.233 0.0"/>
    <parent link="base_link"/>
    <child link="dummy_r"/>
  </joint>
  <joint name="l_arm_mount_joint" type="fixed">
    <origin rpy="0 0 0" xyz="0.0 0.233 0.0"/>
    <parent link="base_link"/>
    <child link="dummy_l"/>
  </joint>
  <link name="dummy_r">
    </link>
  <link name="dummy_l">
    </link>
  <joint name="roll_r" type="fixed">
    <origin rpy="0 0.0 0.0" xyz="0 0.0 0.0"/>
    <parent link="dummy_r"/>
    <child link="r_arm_mount_frame"/>
  </joint>
  <joint name="roll_l" type="fixed">
    <origin rpy="0 0.0 0.0" xyz="0 0.0 0.0"/>
    <parent link="dummy_l"/>
    <child link="l_arm_mount_frame"/>
  </joint>
  <link name="r_arm_mount_frame">
    <!-- dummy intertia to make Gazebo urdf2sdf converter work -->
    <inertial>
      <mass value="1.00000000000001e-06"/>
      <origin xyz="0 0 0"/>
      <inertia ixx="0" ixy="0" ixz="0" iyy="0" iyz="0" izz="0"/>
    </inertial>
  </link>
  <link name="l_arm_mount_frame">
    <!-- dummy intertia to make Gazebo urdf2sdf converter work -->
    <inertial>
      <mass value="1.00000000000001e-06"/>
      <origin xyz="0 0 0"/>
      <inertia ixx="0" ixy="0" ixz="0" iyy="0" iyz="0" izz="0"/>
    </inertial>
  </link>
  <!-- id: 1 for right arm, everything else is considered left arm -->
  <!-- base_link: name of base link a the single arm -->
  <!-- is_sliding_wrist: whether to add a sliding joint along the axis of wrist's second d.o.f.
    (true -> yes), everything else -> no -->
  <joint name="arm_1_joint_1" type="revolute">
    <origin rpy="1.57079632679 0 0" xyz="0 0 0"/>
    <parent link="r_arm_mount_frame"/>
    <child link="arm_1_link_1"/>
    <axis xyz="0 0 1"/>
    <limit effort="200.0" lower="-2.6179938779916667" upper="2.6179938779916667" velocity="10.0"/>
  </joint>
  <link name="arm_1_link_1">
    <inertial>
      <mass value="2"/>
      <inertia ixx="0.0015" ixy="-9.999999999999999e-05" ixz="0.0" iyy="0.0026999999999999997" iyz="9.999999999999999e-05" izz="0.0028"/>
      <origin xyz="0 0 -0.01"/>
    </inertial>
    <collision name="arm_1_link_1_collision">
      <geometry>
        <mesh filename="package://repair_urdf/meshes/base_meshes/link_1.stl" scale="0.001 0.001 0.001"/>
      </geometry>
      <material name="dark"/>
    </collision>
    <visual name="arm_1_link_1_visual">
      <geometry>
        <mesh filename="package://repair_urdf/meshes/base_meshes/link_1.stl" scale="0.001 0.001 0.001"/>
      </geometry>
      <material name="dark"/>
    </visual>
  </link>
  <joint name="arm_1_joint_2" type="revolute">
    <origin rpy="0 -1.57079632679 -3.14159265359" xyz="0.0385 -0.023 0"/>
    <parent link="arm_1_link_1"/>
    <child link="arm_1_link_2"/>
    <axis xyz="0 0 1"/>
    <limit effort="200.0" lower="-1.3962634015955555" upper="2.1816615649930555" velocity="10.0"/>
  </joint>
  <link name="arm_1_link_2">
    <inertial>
      <mass value="0.4"/>
      <inertia ixx="0.00067" ixy="0.0" ixz="0.00017999999999999998" iyy="0.0009699999999999999" iyz="0.0" izz="0.001"/>
      <origin xyz="0.04 0.0 0.035"/>
    </inertial>
    <collision name="arm_1_link_2_collision">
      <geometry>
        <mesh filename="package://repair_urdf/meshes/base_meshes/link_2.stl" scale="0.001 0.001 0.001"/>
      </geometry>
      <material name="dark"/>
    </collision>
    <visual name="arm_1_link_2_visual">
      <geometry>
        <mesh filename="package://repair_urdf/meshes/base_meshes/link_2.stl" scale="0.001 0.001 0.001"/>
      </geometry>
      <material name="dark"/>
    </visual>
  </link>
  <joint name="arm_1_joint_3" type="revolute">
    <origin rpy="0 1.57079632679 0" xyz="0.005 0 0"/>
    <origin rpy="0 -1.57079632679 -3.14159265359" xyz="0.005 0 0"/>
    <parent link="arm_1_link_2"/>
    <child link="arm_1_link_3"/>
    <axis xyz="0 0 1"/>
    <limit effort="200.0" lower="-2.6179938779916667" upper="2.6179938779916667" velocity="10.0"/>
  </joint>
  <link name="arm_1_link_3">
    <inertial>
      <mass value="3.3"/>
      <inertia ixx="0.024999999999999998" ixy="0.0" ixz="0.0" iyy="0.026" iyz="0.0" izz="0.022"/>
      <origin xyz="0.0 -0.025 0.23"/>
    </inertial>
    <collision name="arm_1_link_3_collision">
      <geometry>
        <mesh filename="package://repair_urdf/meshes/base_meshes/link_3.stl" scale="0.001 0.001 0.001"/>
      </geometry>
      <material name="dark"/>
    </collision>
    <visual name="arm_1_link_3_visual">
      <geometry>
        <mesh filename="package://repair_urdf/meshes/base_meshes/link_3.stl" scale="0.001 0.001 0.001"/>
      </geometry>
      <material name="dark"/>
    </visual>
  </link>
  <joint name="arm_1_joint_4" type="revolute">
    <origin rpy="0 -1.57079632679 -3.14159265359" xyz="0 0.0225 0.36014999999999997"/>
    <parent link="arm_1_link_3"/>
    <child link="arm_1_link_4"/>
    <axis xyz="0 0 1"/>
    <limit effort="200.0" lower="-2.6179938779916667" upper="1.0471975511966667" velocity="10.0"/>
  </joint>
  <link name="arm_1_link_4">
    <inertial>
      <mass value="0.4"/>
      <inertia ixx="0.00067" ixy="0.0" ixz="0.00017999999999999998" iyy="0.0009699999999999999" iyz="0.0" izz="0.001"/>
      <origin xyz="0.04 0.0 0.035"/>
    </inertial>
    <collision name="arm_1_link_4_collision">
      <geometry>
        <mesh filename="package://repair_urdf/meshes/base_meshes/link_4.stl" scale="0.001 0.001 0.001"/>
      </geometry>
      <material name="dark"/>
    </collision>
    <visual name="arm_1_link_4_visual">
      <geometry>
        <mesh filename="package://repair_urdf/meshes/base_meshes/link_4.stl" scale="0.001 0.001 0.001"/>
      </geometry>
      <material name="dark"/>
    </visual>
  </link>
  <joint name="arm_1_joint_5" type="revolute">
    <origin rpy="-1.57079632679 0 -1.57079632679" xyz="0.005 0 0"/>
    <parent link="arm_1_link_4"/>
    <child link="arm_1_link_5"/>
    <axis xyz="0 0 1"/>
    <limit effort="200.0" lower="-2.6179938779916667" upper="2.6179938779916667" velocity="10.0"/>
  </joint>
  <link name="arm_1_link_5">
    <inertial>
      <mass value="2.8"/>
      <inertia ixx="0.032" ixy="0.0" ixz="0.0017" iyy="0.033999999999999996" iyz="0.0" izz="0.028999999999999998"/>
      <origin xyz="-0.005 0.0 0.2"/>
    </inertial>
    <collision name="arm_1_link_5_collision">
      <origin rpy="0 0 0" xyz="0 0 0"/>
      <geometry>
        <mesh filename="package://repair_urdf/meshes/base_meshes/link_5.stl" scale="0.001 0.001 0.001"/>
      </geometry>
      <material name="dark"/>
    </collision>
    <visual name="arm_1_link_5_visual">
      <origin rpy="0 0 0" xyz="0 0 0"/>
      <geometry>
        <mesh filename="package://repair_urdf/meshes/base_meshes/link_5.stl" scale="0.001 0.001 0.001"/>
      </geometry>
      <material name="dark"/>
    </visual>
  </link>
  <joint name="arm_1_joint_6" type="revolute">
    <origin rpy="0 -1.57079632679 0" xyz="0 0.0 0.321 "/>
    <axis xyz="0 0 1"/>
    <parent link="arm_1_link_5"/>
    <child link="dummy_sliding_wrist1_link"/>
    <limit effort="200.0" lower="-2.6179938779916667" upper="2.6179938779916667" velocity="10.0"/>
  </joint>
  <link name="dummy_sliding_wrist1_link">
    
    </link>
  <joint name="dummy_sliding_wrist1_joint" type="fixed">
    <origin rpy="0 0 0" xyz="0.0 0.0 -0.0"/>
    <parent link="dummy_sliding_wrist1_link"/>
    <child link="arm_1_link_6"/>
  </joint>
  <link name="arm_1_link_6">
    <inertial>
      <mass value="1.8"/>
      <inertia ixx="0.0017" ixy="0.0" ixz="0.0" iyy="0.0025" iyz="9.999999999999999e-05" izz="0.0026999999999999997"/>
      <origin xyz="0.0 0.0 0.0"/>
    </inertial>
    <collision name="arm_1_link_6_collision">
      <origin rpy="0 0 0" xyz="0 0 0"/>
      <geometry>
        <mesh filename="package://repair_urdf/meshes/base_meshes/link_6.stl" scale="0.001 0.001 0.001"/>
      </geometry>
      <material name="dark"/>
    </collision>
    <visual name="arm_1_link_6_visual">
      <origin rpy="0 0 0" xyz="0 0 0"/>
      <geometry>
        <mesh filename="package://repair_urdf/meshes/base_meshes/link_6.stl" scale="0.001 0.001 0.001"/>
      </geometry>
      <material name="dark"/>
    </visual>
  </link>
  <joint name="arm_1_joint_7" type="revolute">
    <origin rpy="1.57079632679 0 1.57079632679" xyz="0.18 0 0"/>
    <parent link="arm_1_link_6"/>
    <child link="arm_1_link_7"/>
    <axis xyz="0 0 1"/>
    <limit effort="200.0" lower="-2.6179938779916667" upper="2.6179938779916667" velocity="10.0"/>
  </joint>
  <link name="arm_1_link_7">
    <inertial>
      <mass value="1.5"/>
      <inertia ixx="0.024999999999999998" ixy="0.0" ixz="0.0" iyy="0.024999999999999998" iyz="9.999999999999999e-05" izz="0.023"/>
      <origin xyz="0.0 0.0 0.0"/>
    </inertial>
  </link>
  <joint name="arm_1_tcp_joint" type="fixed">
    <origin rpy="0 -2.3561944901874483 -1.57079632679" xyz="0 -0.014142135623730949 0.02414213562373095"/>
    <parent link="arm_1_link_7"/>
    <child link="arm_1_tcp"/>
  </joint>
  <link name="arm_1_tcp">
    <visual name="arm_1_tcp_visual">
      <origin rpy="0 0 0" xyz="0 0 0.02"/>
      <geometry>
        <mesh filename="package://repair_urdf/meshes/link_7_sh.stl" scale="0.001 0.001 0.001"/>
      </geometry>
      <material name="dark"/>
    </visual>
  </link>
  <!-- id: 1 for right arm, everything else is considered left arm -->
  <!-- base_link: name of base link a the single arm -->
  <!-- is_sliding_wrist: whether to add a sliding joint along the axis of wrist's second d.o.f.
    (true -> yes), everything else -> no -->
  <joint name="arm_2_joint_1" type="revolute">
    <origin rpy="-1.57079632679 0 0" xyz="0 0 0"/>
    <parent link="l_arm_mount_frame"/>
    <child link="arm_2_link_1"/>
    <axis xyz="0 0 1"/>
    <limit effort="200.0" lower="-2.6179938779916667" upper="2.6179938779916667" velocity="10.0"/>
  </joint>
  <link name="arm_2_link_1">
    <inertial>
      <mass value="2"/>
      <inertia ixx="0.0015" ixy="-9.999999999999999e-05" ixz="0.0" iyy="0.0026999999999999997" iyz="9.999999999999999e-05" izz="0.0028"/>
      <origin xyz="0 0 -0.01"/>
    </inertial>
    <collision name="arm_2_link_1_collision">
      <geometry>
        <mesh filename="package://repair_urdf/meshes/base_meshes/link_1_mirror.stl" scale="0.001 0.001 0.001"/>
      </geometry>
      <material name="dark"/>
    </collision>
    <visual name="arm_2_link_1_visual">
      <geometry>
        <mesh filename="package://repair_urdf/meshes/base_meshes/link_1_mirror.stl" scale="0.001 0.001 0.001"/>
      </geometry>
      <material name="dark"/>
    </visual>
  </link>
  <joint name="arm_2_joint_2" type="revolute">
    <origin rpy="0 -1.57079632679 -3.14159265359" xyz="0.0385 0.023 0"/>
    <parent link="arm_2_link_1"/>
    <child link="arm_2_link_2"/>
    <axis xyz="0 0 1"/>
    <limit effort="200.0" lower="-1.3962634015955555" upper="2.1816615649930555" velocity="10.0"/>
  </joint>
  <link name="arm_2_link_2">
    <inertial>
      <mass value="0.4"/>
      <inertia ixx="0.00067" ixy="0.0" ixz="0.00017999999999999998" iyy="0.0009699999999999999" iyz="0.0" izz="0.001"/>
      <origin xyz="0.04 0.0 0.035"/>
    </inertial>
    <collision name="arm_2_link_2_collision">
      <geometry>
        <mesh filename="package://repair_urdf/meshes/base_meshes/link_2.stl" scale="0.001 0.001 0.001"/>
      </geometry>
      <material name="dark"/>
    </collision>
    <visual name="arm_2_link_2_visual">
      <geometry>
        <mesh filename="package://repair_urdf/meshes/base_meshes/link_2.stl" scale="0.001 0.001 0.001"/>
      </geometry>
      <material name="dark"/>
    </visual>
  </link>
  <joint name="arm_2_joint_3" type="revolute">
    <origin rpy="0 -1.57079632679 -3.14159265359" xyz="0.005 0 0"/>
    <parent link="arm_2_link_2"/>
    <child link="arm_2_link_3"/>
    <axis xyz="0 0 1"/>
    <limit effort="200.0" lower="-2.6179938779916667" upper="2.6179938779916667" velocity="10.0"/>
  </joint>
  <link name="arm_2_link_3">
    <inertial>
      <mass value="3.3"/>
      <inertia ixx="0.024999999999999998" ixy="0.0" ixz="0.0" iyy="0.026" iyz="0.0" izz="0.022"/>
      <origin xyz="0.0 -0.025 0.23"/>
    </inertial>
    <collision name="arm_2_link_3_collision">
      <geometry>
        <mesh filename="package://repair_urdf/meshes/base_meshes/link_3.stl" scale="0.001 0.001 0.001"/>
      </geometry>
      <material name="dark"/>
    </collision>
    <visual name="arm_2_link_3_visual">
      <geometry>
        <mesh filename="package://repair_urdf/meshes/base_meshes/link_3.stl" scale="0.001 0.001 0.001"/>
      </geometry>
      <material name="dark"/>
    </visual>
  </link>
  <joint name="arm_2_joint_4" type="revolute">
    <origin rpy="0 -1.57079632679 -3.14159265359" xyz="0 0.0225 0.36014999999999997"/>
    <parent link="arm_2_link_3"/>
    <child link="arm_2_link_4"/>
    <axis xyz="0 0 1"/>
    <limit effort="200.0" lower="-2.6179938779916667" upper="1.0471975511966667" velocity="10.0"/>
  </joint>
  <link name="arm_2_link_4">
    <inertial>
      <mass value="0.4"/>
      <inertia ixx="0.00067" ixy="0.0" ixz="0.00017999999999999998" iyy="0.0009699999999999999" iyz="0.0" izz="0.001"/>
      <origin xyz="0.04 0.0 0.035"/>
    </inertial>
    <collision name="arm_2_link_4_collision">
      <geometry>
        <mesh filename="package://repair_urdf/meshes/base_meshes/link_4.stl" scale="0.001 0.001 0.001"/>
      </geometry>
      <material name="dark"/>
    </collision>
    <visual name="arm_2_link_4_visual">
      <geometry>
        <mesh filename="package://repair_urdf/meshes/base_meshes/link_4.stl" scale="0.001 0.001 0.001"/>
      </geometry>
      <material name="dark"/>
    </visual>
  </link>
  <joint name="arm_2_joint_5" type="revolute">
    <origin rpy="-1.57079632679 0 -1.57079632679" xyz="0.005 0 0"/>
    <parent link="arm_2_link_4"/>
    <child link="arm_2_link_5"/>
    <axis xyz="0 0 1"/>
    <limit effort="200.0" lower="-2.6179938779916667" upper="2.6179938779916667" velocity="10.0"/>
  </joint>
  <link name="arm_2_link_5">
    <inertial>
      <mass value="2.8"/>
      <inertia ixx="0.032" ixy="0.0" ixz="0.0017" iyy="0.033999999999999996" iyz="0.0" izz="0.028999999999999998"/>
      <origin xyz="-0.005 0.0 0.2"/>
    </inertial>
    <collision name="arm_2_link_5_collision">
      <origin rpy="0 0 0" xyz="0 0 0"/>
      <geometry>
        <mesh filename="package://repair_urdf/meshes/base_meshes/link_5.stl" scale="0.001 0.001 0.001"/>
      </geometry>
      <material name="dark"/>
    </collision>
    <visual name="arm_2_link_5_visual">
      <origin rpy="0 0 0" xyz="0 0 0"/>
      <geometry>
        <mesh filename="package://repair_urdf/meshes/base_meshes/link_5.stl" scale="0.001 0.001 0.001"/>
      </geometry>
      <material name="dark"/>
    </visual>
  </link>
  <joint name="arm_2_joint_6" type="revolute">
    <origin rpy="0 -1.57079632679 0" xyz="0 0.0 0.321 "/>
    <axis xyz="0 0 1"/>
    <parent link="arm_2_link_5"/>
    <child link="dummy_sliding_wrist2_link"/>
    <limit effort="200.0" lower="-2.6179938779916667" upper="2.6179938779916667" velocity="10.0"/>
  </joint>
  <link name="dummy_sliding_wrist2_link">
    
    </link>
  <joint name="dummy_sliding_wrist2_joint" type="fixed">
    <origin rpy="0 0 0" xyz="0.0 0.0 -0.0"/>
    <parent link="dummy_sliding_wrist2_link"/>
    <child link="arm_2_link_6"/>
  </joint>
  <link name="arm_2_link_6">
    <inertial>
      <mass value="1.8"/>
      <inertia ixx="0.0017" ixy="0.0" ixz="0.0" iyy="0.0025" iyz="9.999999999999999e-05" izz="0.0026999999999999997"/>
      <origin xyz="0.0 0.0 0.0"/>
    </inertial>
    <collision name="arm_2_link_6_collision">
      <origin rpy="0 0 0" xyz="0 0 0"/>
      <geometry>
        <mesh filename="package://repair_urdf/meshes/base_meshes/link_6.stl" scale="0.001 0.001 0.001"/>
      </geometry>
      <material name="dark"/>
    </collision>
    <visual name="arm_2_link_6_visual">
      <origin rpy="0 0 0" xyz="0 0 0"/>
      <geometry>
        <mesh filename="package://repair_urdf/meshes/base_meshes/link_6.stl" scale="0.001 0.001 0.001"/>
      </geometry>
      <material name="dark"/>
    </visual>
  </link>
  <joint name="arm_2_joint_7" type="revolute">
    <origin rpy="-1.57079632679 3.14159265359 -1.57079632679" xyz="0.18 0 0"/>
    <!-- <origin xyz="${180.000 * mmTom} 0 0" rpy="${-PI_2} 0 ${-PI_2}"/> -->
    <parent link="arm_2_link_6"/>
    <child link="arm_2_link_7"/>
    <axis xyz="0 0 1"/>
    <limit effort="200.0" lower="-2.6179938779916667" upper="2.6179938779916667" velocity="10.0"/>
  </joint>
  <link name="arm_2_link_7">
    <inertial>
      <mass value="1.5"/>
      <inertia ixx="0.024999999999999998" ixy="0.0" ixz="0.0" iyy="0.024999999999999998" iyz="9.999999999999999e-05" izz="0.023"/>
      <origin xyz="0.0 0.0 0.0"/>
    </inertial>
  </link>
  <joint name="arm_2_tcp_joint" type="fixed">
    <origin rpy="0 -2.3561944901874483 -1.57079632679" xyz="0 -0.014142135623730949 0.02414213562373095"/>
    <parent link="arm_2_link_7"/>
    <child link="arm_2_tcp"/>
  </joint>
  <link name="arm_2_tcp">
    <visual name="arm_2_tcp_visual">
      <origin rpy="0 0 0" xyz="0 0 0.02"/>
      <geometry>
        <mesh filename="package://repair_urdf/meshes/link_7_rh.stl" scale="0.001 0.001 0.001"/>
      </geometry>
      <material name="dark"/>
    </visual>
  </link>
  <gazebo reference="arm_1_link_1">
    <material>Gazebo/BlackTransparent   </material>
  </gazebo>
  <gazebo reference="arm_1_link_2">
    <material>Gazebo/GreenTransparent    </material>
  </gazebo>
  <gazebo reference="arm_1_link_3">
    <material>Gazebo/BlackTransparent   </material>
  </gazebo>
  <gazebo reference="arm_1_link_4">
    <material>Gazebo/GreenTransparent    </material>
  </gazebo>
  <gazebo reference="arm_1_link_5">
    <material>Gazebo/BlackTransparent  </material>
  </gazebo>
  <gazebo reference="arm_1_link_6">
    <material>Gazebo/GreenTransparent    </material>
  </gazebo>
  <gazebo reference="arm_1_link_7">
    <material>Gazebo/BlackTransparent  </material>
  </gazebo>
  <gazebo reference="arm_1_tcp">
    <material>Gazebo/GreyTransparent    </material>
  </gazebo>
  <gazebo reference="arm_2_link_1">
    <material>Gazebo/BlackTransparent   </material>
  </gazebo>
  <gazebo reference="arm_2_link_2">
    <material>Gazebo/GreenTransparent    </material>
  </gazebo>
  <gazebo reference="arm_2_link_3">
    <material>Gazebo/BlackTransparent   </material>
  </gazebo>
  <gazebo reference="arm_2_link_4">
    <material>Gazebo/GreenTransparent    </material>
  </gazebo>
  <gazebo reference="arm_2_link_5">
    <material>Gazebo/BlackTransparent  </material>
  </gazebo>
  <gazebo reference="arm_2_link_6">
    <material>Gazebo/GreenTransparent    </material>
  </gazebo>
  <gazebo reference="arm_2_link_7">
    <material>Gazebo/BlackTransparent  </material>
  </gazebo>
  <gazebo reference="arm_2_tcp">
    <material>Gazebo/GreyTransparent    </material>
  </gazebo>
  <gazebo reference="base_link">
    <material>Gazebo/GreenTransparent   </material>
  </gazebo>
</robot>
